<?xml version="1.0" encoding="utf-8"?>
<!-- =================================================================================== -->
<!-- |    This document was autogenerated by xacro from mini_cheetah_control.urdf      | -->
<!-- |    EDITING THIS FILE BY HAND IS NOT RECOMMENDED                                 | -->
<!-- =================================================================================== -->
<robot name="mini_cheetah">
  <link name="trunk">
    <inertial>
      <mass value="3.3"/>
      <origin xyz="0.0 0.0 0.0"/>
      <inertia ixx="1.0" ixy="0.0" ixz="0.0" iyy="1.0" iyz="0.0" izz="1.0" />
    </inertial>
    <visual>
      <geometry>
        <mesh filename="package://cheetah_description/meshes/mini_body.stl"/>
      </geometry>
      <origin rpy="0.0 0.0 0.0" xyz="0.0 0.0 0.0"/>
    </visual>
    <collision>
      <geometry>
        <mesh filename="package://cheetah_description/meshes/mini_body.stl"/>
      </geometry>
      <origin rpy="0 0 0" xyz="0 0 0"/>
    </collision>
  </link>
  <!--!!!!!!!!!!!! Front Right Leg !!!!!!!!!!!!!!!!!!!!!!!!!!!!!!!!!!!!-->
  <joint name="FR_hip_joint" type="continuous">
    <axis xyz="1 0 0"/>
    <!-- <origin rpy="1.57079632679 0 1.57079632679" xyz="0.19 -0.049 0.0"/> -->
    <origin rpy="0 0 0" xyz="0.19 -0.049 0.0"/>
    <parent link="trunk"/>
    <child link="FR_hip"/>
  </joint>
  <link name="FR_hip">
    <inertial>
      <mass value="0.5"/>
      <origin xyz="0.0 0.036 0."/>
      <inertia ixx="1.0" ixy="0.0" ixz="0.0" iyy="1.0" iyz="0.0" izz="1.0" />
    </inertial>
    <visual>
      <geometry>
        <mesh filename="package://cheetah_description/meshes/mini_abad.stl"/>
      </geometry>
      <!-- <origin rpy="1.5708 0 0" xyz="0 0 -0.055"/> -->
      <origin rpy="0 -3.1416 -1.5708" xyz="-0.055 0 0"/>
    </visual>
    <collision>
      <geometry>
        <mesh filename="package://cheetah_description/meshes/mini_abad.stl"/>
      </geometry>
      <!-- <origin rpy="1.5708 0 0" xyz="0 0 -0.055"/> -->
      <origin rpy="0 -3.1416 -1.5708" xyz="-0.055 0 0"/>
    </collision>
  </link>
  <joint name="FR_thigh_joint" type="continuous">
    <axis xyz="0 1 0"/>
    <!-- <origin rpy="0.0 1.5708 0.0" xyz="-0.062 0 0.00"/> -->
    <origin rpy="0.0 0.0 0.0" xyz="0 -0.062 0"/>
    <parent link="FR_hip"/>
    <child link="FR_thigh"/>
  </joint>
  <link name="FR_thigh">
    <inertial>
      <mass value="0.634"/>
      <origin xyz="0.0 0.016 -0.02"/>
      <inertia ixx="1.0" ixy="0.0" ixz="0.0" iyy="1.0" iyz="0.0" izz="1.0" />
    </inertial>
    <visual>
      <geometry>
        <mesh filename="package://cheetah_description/meshes/mini_upper_link.stl"/>
      </geometry>
      <!-- <origin rpy="-1.507  0 3.14" xyz="0.0 0.0 0.0"/> -->
      <origin rpy="0 -1.5708 0" xyz="0.0 0.0 0.0"/>
    </visual>
    <collision>
      <geometry>
        <mesh filename="package://cheetah_description/meshes/mini_upper_link.stl"/>
      </geometry>
      <!-- <origin rpy="-1.507  0 3.14" xyz="0.0 0.0 0.0"/> -->
      <origin rpy="0 -1.5708 0" xyz="0.0 0.0 0.0"/>
    </collision>
  </link>
  <joint name="FR_calf_joint" type="continuous">
    <axis xyz="0 1 0"/>
    <!-- <origin rpy="0.0 0 0.0" xyz="0.209 0 0 "/> -->
    <origin rpy="0.0 0 0.0" xyz="0 0 -0.209 "/>
    <parent link="FR_thigh"/>
    <child link="FR_calf"/>
  </joint>
  <link name="FR_calf">
    <inertial>
      <mass value="0.064"/>
      <origin xyz="0.0 0.0 -0.209"/>
      <inertia ixx="1.0" ixy="0.0" ixz="0.0" iyy="1.0" iyz="0.0" izz="1.0" />
    </inertial>
    <visual>
      <geometry>
        <mesh filename="package://cheetah_description/meshes/mini_lower_link.stl"/>
      </geometry>
      <!-- <origin rpy="-1.57070 0 -1.5707" xyz="0.0 0.0 0.0"/> -->
      <origin rpy="0 3.1416 0" xyz="0.0 0.0 0.0"/>
    </visual>
    <collision>
      <geometry>
        <mesh filename="package://cheetah_description/meshes/mini_lower_link.stl"/>
      </geometry>
      <!-- <origin rpy="-1.57070 0 -1.5707" xyz="0.0 0.0 0.0"/> -->
      <origin rpy="0 3.1416 0" xyz="0.0 0.0 0.0"/>
    </collision>
  </link>
  <link name="FR_foot">
    <!-- <contact>
            <friction_anchor/>
            <stiffness value="30000.0"/>
            <damping value="1000.0"/>
            <spinning_friction value="0.3"/>
            <lateral_friction value="3.0"/>
        </contact> -->
    <visual>
      <origin rpy="0 0 0" xyz="0 0 0"/>
      <geometry>
        <sphere radius="0.015"/>
      </geometry>
      <material name="yellow"/>
    </visual>
    <collision>
      <origin rpy="0 0 0" xyz="0 0 0"/>
      <geometry>
        <sphere radius="0.015"/>
      </geometry>
    </collision>
    <inertial>
      <mass value="0.15"/>
      <inertia ixx="1.0" ixy="0.0" ixz="0.0" iyy="1.0" iyz="0.0" izz="1.0" />
    </inertial>
  </link>
  <joint name="FR_foot_fixed" type="fixed">
    <parent link="FR_calf"/>
    <child link="FR_foot"/>
    <!-- <origin xyz="0.18 0 0"/> -->
    <origin xyz="0 0 -0.18"/>
    <dynamics damping="0.0" friction="0.0"/>
  </joint>
  <!--!!!!!!!!!!!! Front Left Leg !!!!!!!!!!!!!!!!!!!!!!!!!!!!!!!!!!!!-->
  <joint name="FL_hip_joint" type="continuous">
    <axis xyz="1 0 0"/>
    <!-- <origin rpy="1.5708 0 1.5708" xyz="0.19 0.049 0.0"/> -->
    <origin rpy="0 0 0" xyz="0.19 0.049 0.0"/>
    <parent link="trunk"/>
    <child link="FL_hip"/>
  </joint>
  <link name="FL_hip">
    <inertial>
      <mass value="0.5"/>
      <origin xyz="0.0 0.036 0."/>
      <inertia ixx="1.0" ixy="0.0" ixz="0.0" iyy="1.0" iyz="0.0" izz="1.0" />
    </inertial>
    <visual>
      <geometry>
        <mesh filename="package://cheetah_description/meshes/mini_abad.stl"/>
      </geometry>
      <!-- <origin rpy="1.5708 0. 3.14159" xyz="0 0.0 -0.055"/> -->
      <origin rpy="0 0 -1.5708" xyz="-0.055 0.0 0"/>
    </visual>
    <collision>
      <geometry>
        <mesh filename="package://cheetah_description/meshes/mini_abad.stl"/>
      </geometry>
      <!-- <origin rpy="1.5708 0. 3.14159" xyz="0 0.0 -0.055"/> -->
      <origin rpy="0 0 -1.5708" xyz="-0.055 0.0 0"/>
    </collision>
  </link>
  <joint name="FL_thigh_joint" type="continuous">
    <axis xyz="0 1 0"/>
    <!-- <origin rpy="0.0 1.5708 0.0" xyz="0.062 0 0.00"/> -->
    <origin rpy="0.0 0 0.0" xyz="0 0.062 0"/>
    <parent link="FL_hip"/>
    <child link="FL_thigh"/>
  </joint>
  <link name="FL_thigh">
    <inertial>
      <mass value="0.634"/>
      <origin xyz="0.0 0.016 -0.02"/>
      <inertia ixx="1.0" ixy="0.0" ixz="0.0" iyy="1.0" iyz="0.0" izz="1.0" />
    </inertial>
    <visual>
      <geometry>
        <mesh filename="package://cheetah_description/meshes/mini_upper_link.stl"/>
      </geometry>
      <!-- <origin rpy="1.5708 0  3.14159" xyz="0.0 0.0 0.0"/> -->
      <origin rpy="0 -1.5708 0" xyz="0.0 0.0 0.0"/>
    </visual>
    <collision>
      <geometry>
        <mesh filename="package://cheetah_description/meshes/mini_upper_link.stl"/>
      </geometry>
      <!-- <origin rpy="1.5708 0  3.14159" xyz="0.0 0.0 0.0"/> -->
      <origin rpy="0 -1.5708 0" xyz="0.0 0.0 0.0"/>
    </collision>
  </link>
  <joint name="FL_calf_joint" type="continuous">
    <axis xyz="0 1 0"/>
    <!-- <origin rpy="0.0 0 0.0" xyz="0.209 0.0 0"/> -->
    <origin rpy="0.0 0 0.0" xyz="0 0 -0.209"/>
    <parent link="FL_thigh"/>
    <child link="FL_calf"/>
  </joint>
  <link name="FL_calf">
    <inertial>
      <mass value="0.064"/>
      <origin xyz="0.0 0.0 -0.209"/>
      <inertia ixx="1.0" ixy="0.0" ixz="0.0" iyy="1.0" iyz="0.0" izz="1.0" />
    </inertial>
    <visual>
      <geometry>
        <mesh filename="package://cheetah_description/meshes/mini_lower_link.stl"/>
      </geometry>
      <!-- <origin rpy="-1.57070 0 -1.5707" xyz="0.0 0.0 0.0"/> -->
      <origin rpy="0 3.1416 0" xyz="0.0 0.0 0.0"/>
    </visual>
    <collision>
      <geometry>
        <mesh filename="package://cheetah_description/meshes/mini_lower_link.stl"/>
      </geometry>
      <!-- <origin rpy="-1.57070 0 -1.5707" xyz="0.0 0.0 0.0"/> -->
      <origin rpy="0 3.1416 0" xyz="0.0 0.0 0.0"/>
    </collision>
  </link>
  <link name="FL_foot">
    <!-- <contact>
            <friction_anchor/>
            <stiffness value="30000.0"/>
            <damping value="1000.0"/>
            <spinning_friction value="0.3"/>
            <lateral_friction value="3.0"/>
        </contact> -->
    <visual>
      <origin rpy="0 0 0" xyz="0 0 0"/>
      <geometry>
        <sphere radius="0.015"/>
      </geometry>
      <material name="yellow"/>
    </visual>
    <collision>
      <origin rpy="0 0 0" xyz="0 0 0"/>
      <geometry>
        <sphere radius="0.015"/>
      </geometry>
    </collision>
    <inertial>
      <mass value="0.15"/>
      <inertia ixx="1.0" ixy="0.0" ixz="0.0" iyy="1.0" iyz="0.0" izz="1.0" />
    </inertial>
  </link>
  <joint name="FL_foot_fixed" type="fixed">
    <parent link="FL_calf"/>
    <child link="FL_foot"/>
    <!-- <origin xyz="0.18 0 0"/> -->
    <origin xyz="0 0 -0.18"/>
    <dynamics damping="0.0" friction="0.0"/>
  </joint>
  <!--!!!!!!!!!!!! Hind Right Leg !!!!!!!!!!!!!!!!!!!!!!!!!!!!!!!!!!!!-->
  <joint name="RR_hip_joint" type="continuous">
    <axis xyz="1 0 0"/>
    <!-- <origin rpy="1.57079632679 0 1.57079632679" xyz="-0.19 -0.049 0.0"/> -->
    <origin rpy="0 0 0" xyz="-0.19 -0.049 0.0"/>
    <parent link="trunk"/>
    <child link="RR_hip"/>
  </joint>
  <link name="RR_hip">
    <inertial>
      <mass value="0.5"/>
      <origin xyz="0.0 0.036 0."/>
      <inertia ixx="1.0" ixy="0.0" ixz="0.0" iyy="1.0" iyz="0.0" izz="1.0" />
    </inertial>
    <visual>
      <geometry>
        <mesh filename="package://cheetah_description/meshes/mini_abad.stl"/>
      </geometry>
      <!-- <origin rpy="-1.5708 0 0" xyz="0 0.0 0.055"/> -->
      <origin rpy="0 0 1.5708" xyz="0.055 0 0"/>
    </visual>
    <collision>
      <geometry>
        <mesh filename="package://cheetah_description/meshes/mini_abad.stl"/>
      </geometry>
      <!-- <origin rpy="-1.5708 0 0" xyz="0 0.0 0.055"/> -->
      <origin rpy="0 0 1.5708" xyz="0.055 0 0"/>
    </collision>
  </link>
  <joint name="RR_thigh_joint" type="continuous">
    <axis xyz="0 1 0"/>
    <!-- <origin rpy="0.0 1.5708 0.0" xyz="-0.062 0 0.00"/> -->
    <origin rpy="0.0 0 0.0" xyz="0 -0.062 0"/>
    <parent link="RR_hip"/>
    <child link="RR_thigh"/>
  </joint>
  <link name="RR_thigh">
    <inertial>
      <mass value="0.634"/>
      <origin xyz="0.0 0.016 -0.02"/>
      <inertia ixx="1.0" ixy="0.0" ixz="0.0" iyy="1.0" iyz="0.0" izz="1.0" />
    </inertial>
    <visual>
      <geometry>
        <mesh filename="package://cheetah_description/meshes/mini_upper_link.stl"/>
      </geometry>
      <!-- <origin rpy="-1.5708 0 3.14159" xyz="0.0 0.0 0.0"/> -->
      <origin rpy="0 -1.5708 0" xyz="0.0 0.0 0.0"/>
    </visual>
    <collision>
      <geometry>
        <mesh filename="package://cheetah_description/meshes/mini_upper_link.stl"/>
      </geometry>
      <!-- <origin rpy="-1.5708 0 3.14159" xyz="0.0 0.0 0.0"/> -->
      <origin rpy="0 -1.5708 0" xyz="0.0 0.0 0.0"/>
    </collision>
  </link>
  <joint name="RR_calf_joint" type="continuous">
    <axis xyz="0 1 0"/>
    <!-- <origin rpy="0.0 0 0.0" xyz="0.209 0 0 "/> -->
    <origin rpy="0.0 0 0.0" xyz="0 0 -0.209 "/>
    <parent link="RR_thigh"/>
    <child link="RR_calf"/>
  </joint>
  <link name="RR_calf">
    <inertial>
      <mass value="0.064"/>
      <origin xyz="0.0 0.0 -0.209"/>
      <inertia ixx="1.0" ixy="0.0" ixz="0.0" iyy="1.0" iyz="0.0" izz="1.0" />
    </inertial>
    <visual>
      <geometry>
        <mesh filename="package://cheetah_description/meshes/mini_lower_link.stl"/>
      </geometry>
      <!-- <origin rpy="-1.57070 0 -1.5707" xyz="0.0 0.0 0.0"/> -->
      <origin rpy="0 3.1416 0" xyz="0.0 0.0 0.0"/>
    </visual>
    <collision>
      <geometry>
        <mesh filename="package://cheetah_description/meshes/mini_lower_link.stl"/>
      </geometry>
      <!-- <origin rpy="-1.57070 0 -1.5707" xyz="0.0 0.0 0.0"/> -->
      <origin rpy="0 3.1416 0" xyz="0.0 0.0 0.0"/>
    </collision>
  </link>
  <link name="RR_foot">
    <!-- <contact>
            <friction_anchor/>
            <stiffness value="30000.0"/>
            <damping value="1000.0"/>
            <spinning_friction value="0.3"/>
            <lateral_friction value="3.0"/>
        </contact> -->
    <visual>
      <origin rpy="0 0 0" xyz="0 0 0"/>
      <geometry>
        <sphere radius="0.015"/>
      </geometry>
      <material name="yellow"/>
    </visual>
    <collision>
      <origin rpy="0 0 0" xyz="0 0 0"/>
      <geometry>
        <sphere radius="0.015"/>
      </geometry>
    </collision>
    <inertial>
      <mass value="0.15"/>
      <inertia ixx="1.0" ixy="0.0" ixz="0.0" iyy="1.0" iyz="0.0" izz="1.0" />
    </inertial>
  </link>
  <joint name="RR_foot_fixed" type="fixed">
    <parent link="RR_calf"/>
    <child link="RR_foot"/>
    <child link="FR_foot"/>
    <!-- <origin xyz="0.18 0 0"/> -->
    <origin xyz="0 0 -0.18"/>
    <dynamics damping="0.0" friction="0.0"/>
  </joint>
  <!--!!!!!!!!!!!! Hind Left Leg !!!!!!!!!!!!!!!!!!!!!!!!!!!!!!!!!!!!-->
  <joint name="RL_hip_joint" type="continuous">
    <axis xyz="1 0 0"/>
    <!-- <origin rpy="1.5708 0 1.5708" xyz="-0.19 0.049 0.0"/> -->
    <origin rpy="0 0 0" xyz="-0.19 0.049 0.0"/>
    <parent link="trunk"/>
    <child link="RL_hip"/>
  </joint>
  <link name="RL_hip">
    <inertial>
      <mass value="0.5"/>
      <origin xyz="0.0 0.036 0."/>
      <inertia ixx="1.0" ixy="0.0" ixz="0.0" iyy="1.0" iyz="0.0" izz="1.0" />
    </inertial>
    <visual>
      <geometry>
        <mesh filename="package://cheetah_description/meshes/mini_abad.stl"/>
      </geometry>
      <!-- <origin rpy="-1.5708 0 -3.141592" xyz="0 0.0 0.055"/> -->
      <origin rpy="-3.1416 0 -1.5708" xyz="0.055 0 0"/>
    </visual>
    <collision>
      <geometry>
        <mesh filename="package://cheetah_description/meshes/mini_abad.stl"/>
      </geometry>
      <!-- <origin rpy="-1.5708 0 -3.141592" xyz="0 0.0 0.055"/> -->
      <origin rpy="-3.1416 0 -1.5708" xyz="0.055 0 0"/>
    </collision>
  </link>
  <joint name="RL_thigh_joint" type="continuous">
    <axis xyz="0 1 0"/>
    <!-- <origin rpy="0.0 1.5708 0.0" xyz="-0.062 0 0.00"/> -->
    <origin rpy="0.0 0.0 0.0" xyz="0 0.062 0"/>
    <parent link="RL_hip"/>
    <child link="RL_thigh"/>
  </joint>
  <link name="RL_thigh">
    <inertial>
      <mass value="0.634"/>
      <origin xyz="0.0 0.016 -0.02"/>
      <inertia ixx="1.0" ixy="0.0" ixz="0.0" iyy="1.0" iyz="0.0" izz="1.0" />
    </inertial>
    <visual>
      <geometry>
        <mesh filename="package://cheetah_description/meshes/mini_upper_link.stl"/>
      </geometry>
      <!-- <origin rpy="-1.507  0 3.14" xyz="0.0 0.0 0.0"/> -->
      <origin rpy="0 -1.5708 0" xyz="0.0 0.0 0.0"/>
    </visual>
    <collision>
      <geometry>
        <mesh filename="package://cheetah_description/meshes/mini_upper_link.stl"/>
      </geometry>
      <!-- <origin rpy="-1.507  0 3.14" xyz="0.0 0.0 0.0"/> -->
      <origin rpy="0 -1.5708 0" xyz="0.0 0.0 0.0"/>
    </collision>
  </link>
  <joint name="RL_calf_joint" type="continuous">
    <axis xyz="0 1 0"/>
    <!-- <origin rpy="0.0 0 0.0" xyz="0.209 0 0 "/> -->
    <origin rpy="0.0 0 0.0" xyz="0 0 -0.209 "/>
    <parent link="RL_thigh"/>
    <child link="RL_calf"/>
  </joint>
  <link name="RL_calf">
    <inertial>
      <mass value="0.064"/>
      <origin xyz="0.0 0.0 -0.209"/>
      <inertia ixx="1.0" ixy="0.0" ixz="0.0" iyy="1.0" iyz="0.0" izz="1.0" />
    </inertial>
    <visual>
      <geometry>
        <mesh filename="package://cheetah_description/meshes/mini_lower_link.stl"/>
      </geometry>
      <!-- <origin rpy="-1.57070 0 -1.5707" xyz="0.0 0.0 0.0"/> -->
      <origin rpy="0 3.1416 0" xyz="0.0 0.0 0.0"/>
    </visual>
    <collision>
      <geometry>
        <mesh filename="package://cheetah_description/meshes/mini_lower_link.stl"/>
      </geometry>
      <!-- <origin rpy="-1.57070 0 -1.5707" xyz="0.0 0.0 0.0"/> -->
      <origin rpy="0 3.1416 0" xyz="0.0 0.0 0.0"/>
    </collision>
  </link>
  <link name="RL_foot">
    <!-- <contact>
            <friction_anchor/>
            <stiffness value="30000.0"/>
            <damping value="1000.0"/>
            <spinning_friction value="0.3"/>
            <lateral_friction value="3.0"/>
        </contact> -->
    <visual>
      <origin rpy="0 0 0" xyz="0 0 0"/>
      <geometry>
        <sphere radius="0.015"/>
      </geometry>
      <material name="yellow"/>
    </visual>
    <collision>
      <origin rpy="0 0 0" xyz="0 0 0"/>
      <geometry>
        <sphere radius="0.015"/>
      </geometry>
    </collision>
    <inertial>
      <mass value="0.15"/>
      <inertia ixx="1.0" ixy="0.0" ixz="0.0" iyy="1.0" iyz="0.0" izz="1.0" />
    </inertial>
  </link>
  <joint name="RL_foot_fixed" type="fixed">
    <parent link="RL_calf"/>
    <child link="RL_foot"/>
    <!-- <origin xyz="0.18 0 0"/> -->
    <origin xyz="0 0 -0.18"/>
    <dynamics damping="0.0" friction="0.0"/>
  </joint>
  <transmission name="tran0">
    <type>transmission_interface/SimpleTransmission</type>
    <joint name="FR_hip_joint">
      <hardwareInterface>hardware_interface/EffortJointInterface</hardwareInterface>
    </joint>
    <actuator name="FR_hip_motor">
      <hardwareInterface>hardware_interface/EffortJointInterface</hardwareInterface>
      <!--hardware_interface/-->
      <mechanicalReduction>1</mechanicalReduction>
    </actuator>
  </transmission>
  <transmission name="tran1">
    <type>transmission_interface/SimpleTransmission</type>
    <joint name="FR_thigh_joint">
      <hardwareInterface>hardware_interface/EffortJointInterface</hardwareInterface>
    </joint>
    <actuator name="FR_thigh_motor">
      <hardwareInterface>hardware_interface/EffortJointInterface</hardwareInterface>
      <!--hardware_interface/-->
      <mechanicalReduction>1</mechanicalReduction>
    </actuator>
  </transmission>
  <transmission name="tran2">
    <type>transmission_interface/SimpleTransmission</type>
    <joint name="FR_calf_joint">
      <hardwareInterface>hardware_interface/EffortJointInterface</hardwareInterface>
    </joint>
    <actuator name="FR_calf_motor">
      <hardwareInterface>hardware_interface/EffortJointInterface</hardwareInterface>
      <!--hardware_interface/-->
      <mechanicalReduction>1</mechanicalReduction>
    </actuator>
  </transmission>
  <transmission name="tran3">
    <type>transmission_interface/SimpleTransmission</type>
    <joint name="FL_hip_joint">
      <hardwareInterface>hardware_interface/EffortJointInterface</hardwareInterface>
    </joint>
    <actuator name="FL_hip_motor">
      <hardwareInterface>hardware_interface/EffortJointInterface</hardwareInterface>
      <!--hardware_interface/-->
      <mechanicalReduction>1</mechanicalReduction>
    </actuator>
  </transmission>
  <transmission name="tran4">
    <type>transmission_interface/SimpleTransmission</type>
    <joint name="FL_thigh_joint">
      <hardwareInterface>hardware_interface/EffortJointInterface</hardwareInterface>
    </joint>
    <actuator name="FL_thigh_motor">
      <hardwareInterface>hardware_interface/EffortJointInterface</hardwareInterface>
      <!--hardware_interface/-->
      <mechanicalReduction>1</mechanicalReduction>
    </actuator>
  </transmission>
  <transmission name="tran5">
    <type>transmission_interface/SimpleTransmission</type>
    <joint name="FL_calf_joint">
      <hardwareInterface>hardware_interface/EffortJointInterface</hardwareInterface>
    </joint>
    <actuator name="FL_calf_motor">
      <hardwareInterface>hardware_interface/EffortJointInterface</hardwareInterface>
      <!--hardware_interface/-->
      <mechanicalReduction>1</mechanicalReduction>
    </actuator>
  </transmission>
  <transmission name="tran6">
    <type>transmission_interface/SimpleTransmission</type>
    <joint name="RR_hip_joint">
      <hardwareInterface>hardware_interface/EffortJointInterface</hardwareInterface>
    </joint>
    <actuator name="RR_hip_motor">
      <hardwareInterface>hardware_interface/EffortJointInterface</hardwareInterface>
      <!--hardware_interface/-->
      <mechanicalReduction>1</mechanicalReduction>
    </actuator>
  </transmission>
  <transmission name="tran7">
    <type>transmission_interface/SimpleTransmission</type>
    <joint name="RR_thigh_joint">
      <hardwareInterface>hardware_interface/EffortJointInterface</hardwareInterface>
    </joint>
    <actuator name="RR_thigh_motor">
      <hardwareInterface>hardware_interface/EffortJointInterface</hardwareInterface>
      <!--hardware_interface/-->
      <mechanicalReduction>1</mechanicalReduction>
    </actuator>
  </transmission>
  <transmission name="tran8">
    <type>transmission_interface/SimpleTransmission</type>
    <joint name="RR_calf_joint">
      <hardwareInterface>hardware_interface/EffortJointInterface</hardwareInterface>
    </joint>
    <actuator name="RR_calf_motor">
      <hardwareInterface>hardware_interface/EffortJointInterface</hardwareInterface>
      <!--hardware_interface/-->
      <mechanicalReduction>1</mechanicalReduction>
    </actuator>
  </transmission>
  <transmission name="tran9">
    <type>transmission_interface/SimpleTransmission</type>
    <joint name="RL_hip_joint">
      <hardwareInterface>hardware_interface/EffortJointInterface</hardwareInterface>
    </joint>
    <actuator name="RL_hip_motor">
      <hardwareInterface>hardware_interface/EffortJointInterface</hardwareInterface>
      <!--hardware_interface/-->
      <mechanicalReduction>1</mechanicalReduction>
    </actuator>
  </transmission>
  <transmission name="tran10">
    <type>transmission_interface/SimpleTransmission</type>
    <joint name="RL_thigh_joint">
      <hardwareInterface>hardware_interface/EffortJointInterface</hardwareInterface>
    </joint>
    <actuator name="RL_thigh_motor">
      <hardwareInterface>hardware_interface/EffortJointInterface</hardwareInterface>
      <!--hardware_interface/-->
      <mechanicalReduction>1</mechanicalReduction>
    </actuator>
  </transmission>
  <transmission name="tran11">
    <type>transmission_interface/SimpleTransmission</type>
    <joint name="RL_calf_joint">
      <hardwareInterface>hardware_interface/EffortJointInterface</hardwareInterface>
    </joint>
    <actuator name="RL_calf_motor">
      <hardwareInterface>hardware_interface/EffortJointInterface</hardwareInterface>
      <!--hardware_interface/-->
      <mechanicalReduction>1</mechanicalReduction>
    </actuator>
  </transmission>
  <gazebo reference="RL_hip">
    <material>Gazebo/DarkGrey</material>
  </gazebo>
  <gazebo reference="FR_hip">
    <material>Gazebo/DarkGrey</material>
  </gazebo>
  <gazebo reference="RR_hip">
    <material>Gazebo/DarkGrey</material>
  </gazebo>
  <gazebo reference="FL_hip">
    <material>Gazebo/DarkGrey</material>
  </gazebo>
  <gazebo>
    <plugin filename="libgazebo_ros_control.so" name="gazebo_ros_control">
      <robotNamespace>/mini_chee</robotNamespace>
    </plugin>
  </gazebo>
</robot>

